Workbook

Sheet midterms
A1: # | B1: Student Name | C1: Week 1 | E1: Week 2 | G1: Week 3 | I1: Week 4 | K1: Week 5 | M1: Week 6 | O1: Week 7 | Q1: MIDTERM
C2: Monday, July 21, 2025 | D2: Thursday, July 24, 2025 | E2: Monday, July 28, 2025 | F2: Thursday, July 31, 2025 | G2: Monday, August 4, 2025 | H2: Thursday, August 7, 2025 | I2: Monday, August 11, 2025 | J2: Thursday, August 14, 2025 | K2: Monday, August 18, 2025 | L2: Thursday, August 21, 2025 | M2: Monday, August 25, 2025 | N2: Thursday, August 28, 2025 | O2: Monday, September 1, 2025 | P2: Thursday, September 4, 2025
A3: 1 | B3: ABIERA, KIRK HAMMETT GILBUENA | Q3: =SUMPRODUCT((C3:P3=1)*1+(C3:P3=2)*0.75+(C3:P3=3)*0.69+(C3:P3=4)*0.63)
A4: 2 | B4: AGALOOS, IVAN BENEDICT VILLAMOR | Q4: =SUMPRODUCT((C4:P4=1)*1+(C4:P4=2)*0.75+(C4:P4=3)*0.69+(C4:P4=4)*0.63)
A5: 3 | B5: AGTAGUEM, AL-JOHN ANTE | Q5: =SUMPRODUCT((C5:P5=1)*1+(C5:P5=2)*0.75+(C5:P5=3)*0.69+(C5:P5=4)*0.63)
A6: 4 | B6: AGUILAR, ANGELICA DE LEON | Q6: =SUMPRODUCT((C6:P6=1)*1+(C6:P6=2)*0.75+(C6:P6=3)*0.69+(C6:P6=4)*0.63)
A7: 5 | B7: ALCANTARA, RHEINARD JOHN OLAES | Q7: =SUMPRODUCT((C7:P7=1)*1+(C7:P7=2)*0.75+(C7:P7=3)*0.69+(C7:P7=4)*0.63)
A8: 6 | B8: ALEJANDRE, ROMEL JOHN LLAPITAN | Q8: =SUMPRODUCT((C8:P8=1)*1+(C8:P8=2)*0.75+(C8:P8=3)*0.69+(C8:P8=4)*0.63)
A9: 7 | B9: ALMERIA, JAE MARK LEGARIO | Q9: =SUMPRODUCT((C9:P9=1)*1+(C9:P9=2)*0.75+(C9:P9=3)*0.69+(C9:P9=4)*0.63)
A10: 8 | B10: ALOP, VINCE POCHOLO ALCANTARA | Q10: =SUMPRODUCT((C10:P10=1)*1+(C10:P10=2)*0.75+(C10:P10=3)*0.69+(C10:P10=4)*0.63)
A11: 9 | B11: APOLINARIO, ACE JOHN PAUL SALAZAR | Q11: =SUMPRODUCT((C11:P11=1)*1+(C11:P11=2)*0.75+(C11:P11=3)*0.69+(C11:P11=4)*0.63)
A12: 10 | B12: BEGINO, WIL JUSTIN DAMPIOS | Q12: =SUMPRODUCT((C12:P12=1)*1+(C12:P12=2)*0.75+(C12:P12=3)*0.69+(C12:P12=4)*0.63)
A13: 11 | B13: CADA, MIGUEL EDUARDO GUNO | Q13: =SUMPRODUCT((C13:P13=1)*1+(C13:P13=2)*0.75+(C13:P13=3)*0.69+(C13:P13=4)*0.63)
A14: 12 | B14: CARIAGA, REINARD AMIEL ANCHETA | Q14: =SUMPRODUCT((C14:P14=1)*1+(C14:P14=2)*0.75+(C14:P14=3)*0.69+(C14:P14=4)*0.63)
... A44: 42 | B44: VALIENTE, MARK JUSTINE MORANDARTE | Q44: =SUMPRODUCT((C44:P44=1)*1+(C44:P44=2)*0.75+(C44:P44=3)*0.69+(C44:P44=4)*0.63)

Sheet finals
A1: # | B1: Student Name | C1: Week 8 | E1: Week 9 | G1: Week 10 | I1: Week 11 | K1: Week 12 | M1: Week 13 | O1: Week 14 | Q1: FINAL
C2: Monday, September 8, 2025 | D2: Thursday, September 11, 2025 | E2: Monday, September 15, 2025 | F2: Thursday, September 18, 2025 | G2: Monday, September 22, 2025 | H2: Thursday, September 25, 2025 | I2: Monday, September 29, 2025 | J2: Thursday, October 2, 2025 | K2: Monday, October 6, 2025 | L2: Thursday, October 9, 2025 | M2: Monday, October 13, 2025 | N2: Thursday, October 16, 2025 | O2: Monday, October 20, 2025 | P2: Thursday, October 23, 2025
A3: ='midterms'!A3 | B3: ='midterms'!B3 | Q3: =SUMPRODUCT((C3:P3=1)*1+(C3:P3=2)*0.75+(C3:P3=3)*0.69+(C3:P3=4)*0.63)
A4: ='midterms'!A4 | B4: ='midterms'!B4 | Q4: =SUMPRODUCT((C4:P4=1)*1+(C4:P4=2)*0.75+(C4:P4=3)*0.69+(C4:P4=4)*0.63)
A5: ='midterms'!A5 | B5: ='midterms'!B5 | Q5: =SUMPRODUCT((C5:P5=1)*1+(C5:P5=2)*0.75+(C5:P5=3)*0.69+(C5:P5=4)*0.63)
A6: ='midterms'!A6 | B6: ='midterms'!B6 | Q6: =SUMPRODUCT((C6:P6=1)*1+(C6:P6=2)*0.75+(C6:P6=3)*0.69+(C6:P6=4)*0.63)
A7: ='midterms'!A7 | B7: ='midterms'!B7 | Q7: =SUMPRODUCT((C7:P7=1)*1+(C7:P7=2)*0.75+(C7:P7=3)*0.69+(C7:P7=4)*0.63)
A8: ='midterms'!A8 | B8: ='midterms'!B8 | Q8: =SUMPRODUCT((C8:P8=1)*1+(C8:P8=2)*0.75+(C8:P8=3)*0.69+(C8:P8=4)*0.63)
A9: ='midterms'!A9 | B9: ='midterms'!B9 | Q9: =SUMPRODUCT((C9:P9=1)*1+(C9:P9=2)*0.75+(C9:P9=3)*0.69+(C9:P9=4)*0.63)
A10: ='midterms'!A10 | B10: ='midterms'!B10 | Q10: =SUMPRODUCT((C10:P10=1)*1+(C10:P10=2)*0.75+(C10:P10=3)*0.69+(C10:P10=4)*0.63)
A11: ='midterms'!A11 | B11: ='midterms'!B11 | Q11: =SUMPRODUCT((C11:P11=1)*1+(C11:P11=2)*0.75+(C11:P11=3)*0.69+(C11:P11=4)*0.63)
A12: ='midterms'!A12 | B12: ='midterms'!B12 | Q12: =SUMPRODUCT((C12:P12=1)*1+(C12:P12=2)*0.75+(C12:P12=3)*0.69+(C12:P12=4)*0.63)
A13: ='midterms'!A13 | B13: ='midterms'!B13 | Q13: =SUMPRODUCT((C13:P13=1)*1+(C13:P13=2)*0.75+(C13:P13=3)*0.69+(C13:P13=4)*0.63)
A14: ='midterms'!A14 | B14: ='midterms'!B14 | Q14: =SUMPRODUCT((C14:P14=1)*1+(C14:P14=2)*0.75+(C14:P14=3)*0.69+(C14:P14=4)*0.63)
... A44: ='midterms'!A44 | B44: ='midterms'!B44 | Q44: =SUMPRODUCT((C44:P44=1)*1+(C44:P44=2)*0.75+(C44:P44=3)*0.69+(C44:P44=4)*0.63)

Sheet all
A1: # | B1: Student Name | C1: Week 1 | E1: Week 2 | G1: Week 3 | I1: Week 4 | K1: Week 5 | M1: Week 6 | O1: Week 7 | Q1: Week 8 | S1: Week 9 | U1: Week 10 | W1: Week 11 | Y1: Week 12 | AA1: Week 13 | AC1: Week 14 | AE1: MIDTERM | AG1: FINAL | AI1: TOTAL
C2: Monday, July 21, 2025 | D2: Thursday, July 24, 2025 | E2: Monday, July 28, 2025 | F2: Thursday, July 31, 2025 | G2: Monday, August 4, 2025 | H2: Thursday, August 7, 2025 | I2: Monday, August 11, 2025 | J2: Thursday, August 14, 2025 | K2: Monday, August 18, 2025 | L2: Thursday, August 21, 2025 | M2: Monday, August 25, 2025 | N2: Thursday, August 28, 2025 | O2: Monday, September 1, 2025 | P2: Thursday, September 4, 2025 | Q2: Monday, September 8, 2025 | R2: Thursday, September 11, 2025 | S2: Monday, September 15, 2025 | T2: Thursday, September 18, 2025 | U2: Monday, September 22, 2025 | V2: Thursday, September 25, 2025 | W2: Monday, September 29, 2025 | X2: Thursday, October 2, 2025 | Y2: Monday, October 6, 2025 | Z2: Thursday, October 9, 2025 | AA2: Monday, October 13, 2025 | AB2: Thursday, October 16, 2025 | AC2: Monday, October 20, 2025 | AD2: Thursday, October 23, 2025
A3: ='midterms'!A3 | B3: ='midterms'!B3 | C3: =IF('midterms'!C3="","",'midterms'!C3) | D3: =IF('midterms'!D3="","",'midterms'!D3) | E3: =IF('midterms'!E3="","",'midterms'!E3) | F3: =IF('midterms'!F3="","",'midterms'!F3) | G3: =IF('midterms'!G3="","",'midterms'!G3) | H3: =IF('midterms'!H3="","",'midterms'!H3) | I3: =IF('midterms'!I3="","",'midterms'!I3) | J3: =IF('midterms'!J3="","",'midterms'!J3) | ... P3: =IF('midterms'!P3="","",'midterms'!P3) | Q3: =IF('finals'!C3="","",'finals'!C3) | R3: =IF('finals'!D3="","",'finals'!D3) | S3: =IF('finals'!E3="","",'finals'!E3) | T3: =IF('finals'!F3="","",'finals'!F3) | U3: =IF('finals'!G3="","",'finals'!G3) | V3: =IF('finals'!H3="","",'finals'!H3) | W3: =IF('finals'!I3="","",'finals'!I3) | X3: =IF('finals'!J3="","",'finals'!J3) | ... AD3: =IF('finals'!P3="","",'finals'!P3) | AE3: ='midterms'!Q3 | AG3: ='finals'!Q3 | AI3: =IF(OR(AE3="",AG3=""),IF(AND(AE3="",AG3=""),"",IF(AE3="",AG3,AE3)),AE3+AG3)
A4: ='midterms'!A4 | B4: ='midterms'!B4 | C4: =IF('midterms'!C4="","",'midterms'!C4) | D4: =IF('midterms'!D4="","",'midterms'!D4) | E4: =IF('midterms'!E4="","",'midterms'!E4) | F4: =IF('midterms'!F4="","",'midterms'!F4) | G4: =IF('midterms'!G4="","",'midterms'!G4) | H4: =IF('midterms'!H4="","",'midterms'!H4) | I4: =IF('midterms'!I4="","",'midterms'!I4) | J4: =IF('midterms'!J4="","",'midterms'!J4) | ... P4: =IF('midterms'!P4="","",'midterms'!P4) | Q4: =IF('finals'!C4="","",'finals'!C4) | R4: =IF('finals'!D4="","",'finals'!D4) | S4: =IF('finals'!E4="","",'finals'!E4) | T4: =IF('finals'!F4="","",'finals'!F4) | U4: =IF('finals'!G4="","",'finals'!G4) | V4: =IF('finals'!H4="","",'finals'!H4) | W4: =IF('finals'!I4="","",'finals'!I4) | X4: =IF('finals'!J4="","",'finals'!J4) | ... AD4: =IF('finals'!P4="","",'finals'!P4) | AE4: ='midterms'!Q4 | AG4: ='finals'!Q4 | AI4: =IF(OR(AE4="",AG4=""),IF(AND(AE4="",AG4=""),"",IF(AE4="",AG4,AE4)),AE4+AG4)
A5: ='midterms'!A5 | B5: ='midterms'!B5 | C5: =IF('midterms'!C5="","",'midterms'!C5) | D5: =IF('midterms'!D5="","",'midterms'!D5) | E5: =IF('midterms'!E5="","",'midterms'!E5) | F5: =IF('midterms'!F5="","",'midterms'!F5) | G5: =IF('midterms'!G5="","",'midterms'!G5) | H5: =IF('midterms'!H5="","",'midterms'!H5) | I5: =IF('midterms'!I5="","",'midterms'!I5) | J5: =IF('midterms'!J5="","",'midterms'!J5) | ... P5: =IF('midterms'!P5="","",'midterms'!P5) | Q5: =IF('finals'!C5="","",'finals'!C5) | R5: =IF('finals'!D5="","",'finals'!D5) | S5: =IF('finals'!E5="","",'finals'!E5) | T5: =IF('finals'!F5="","",'finals'!F5) | U5: =IF('finals'!G5="","",'finals'!G5) | V5: =IF('finals'!H5="","",'finals'!H5) | W5: =IF('finals'!I5="","",'finals'!I5) | X5: =IF('finals'!J5="","",'finals'!J5) | ... AD5: =IF('finals'!P5="","",'finals'!P5) | AE5: ='midterms'!Q5 | AG5: ='finals'!Q5 | AI5: =IF(OR(AE5="",AG5=""),IF(AND(AE5="",AG5=""),"",IF(AE5="",AG5,AE5)),AE5+AG5)
A6: ='midterms'!A6 | B6: ='midterms'!B6 | C6: =IF('midterms'!C6="","",'midterms'!C6) | D6: =IF('midterms'!D6="","",'midterms'!D6) | E6: =IF('midterms'!E6="","",'midterms'!E6) | F6: =IF('midterms'!F6="","",'midterms'!F6) | G6: =IF('midterms'!G6="","",'midterms'!G6) | H6: =IF('midterms'!H6="","",'midterms'!H6) | I6: =IF('midterms'!I6="","",'midterms'!I6) | J6: =IF('midterms'!J6="","",'midterms'!J6) | ... P6: =IF('midterms'!P6="","",'midterms'!P6) | Q6: =IF('finals'!C6="","",'finals'!C6) | R6: =IF('finals'!D6="","",'finals'!D6) | S6: =IF('finals'!E6="","",'finals'!E6) | T6: =IF('finals'!F6="","",'finals'!F6) | U6: =IF('finals'!G6="","",'finals'!G6) | V6: =IF('finals'!H6="","",'finals'!H6) | W6: =IF('finals'!I6="","",'finals'!I6) | X6: =IF('finals'!J6="","",'finals'!J6) | ... AD6: =IF('finals'!P6="","",'finals'!P6) | AE6: ='midterms'!Q6 | AG6: ='finals'!Q6 | AI6: =IF(OR(AE6="",AG6=""),IF(AND(AE6="",AG6=""),"",IF(AE6="",AG6,AE6)),AE6+AG6)
A7: ='midterms'!A7 | B7: ='midterms'!B7 | C7: =IF('midterms'!C7="","",'midterms'!C7) | D7: =IF('midterms'!D7="","",'midterms'!D7) | E7: =IF('midterms'!E7="","",'midterms'!E7) | F7: =IF('midterms'!F7="","",'midterms'!F7) | G7: =IF('midterms'!G7="","",'midterms'!G7) | H7: =IF('midterms'!H7="","",'midterms'!H7) | I7: =IF('midterms'!I7="","",'midterms'!I7) | J7: =IF('midterms'!J7="","",'midterms'!J7) | ... P7: =IF('midterms'!P7="","",'midterms'!P7) | Q7: =IF('finals'!C7="","",'finals'!C7) | R7: =IF('finals'!D7="","",'finals'!D7) | S7: =IF('finals'!E7="","",'finals'!E7) | T7: =IF('finals'!F7="","",'finals'!F7) | U7: =IF('finals'!G7="","",'finals'!G7) | V7: =IF('finals'!H7="","",'finals'!H7) | W7: =IF('finals'!I7="","",'finals'!I7) | X7: =IF('finals'!J7="","",'finals'!J7) | ... AD7: =IF('finals'!P7="","",'finals'!P7) | AE7: ='midterms'!Q7 | AG7: ='finals'!Q7 | AI7: =IF(OR(AE7="",AG7=""),IF(AND(AE7="",AG7=""),"",IF(AE7="",AG7,AE7)),AE7+AG7)
A8: ='midterms'!A8 | B8: ='midterms'!B8 | C8: =IF('midterms'!C8="","",'midterms'!C8) | D8: =IF('midterms'!D8="","",'midterms'!D8) | E8: =IF('midterms'!E8="","",'midterms'!E8) | F8: =IF('midterms'!F8="","",'midterms'!F8) | G8: =IF('midterms'!G8="","",'midterms'!G8) | H8: =IF('midterms'!H8="","",'midterms'!H8) | I8: =IF('midterms'!I8="","",'midterms'!I8) | J8: =IF('midterms'!J8="","",'midterms'!J8) | ... P8: =IF('midterms'!P8="","",'midterms'!P8) | Q8: =IF('finals'!C8="","",'finals'!C8) | R8: =IF('finals'!D8="","",'finals'!D8) | S8: =IF('finals'!E8="","",'finals'!E8) | T8: =IF('finals'!F8="","",'finals'!F8) | U8: =IF('finals'!G8="","",'finals'!G8) | V8: =IF('finals'!H8="","",'finals'!H8) | W8: =IF('finals'!I8="","",'finals'!I8) | X8: =IF('finals'!J8="","",'finals'!J8) | ... AD8: =IF('finals'!P8="","",'finals'!P8) | AE8: ='midterms'!Q8 | AG8: ='finals'!Q8 | AI8: =IF(OR(AE8="",AG8=""),IF(AND(AE8="",AG8=""),"",IF(AE8="",AG8,AE8)),AE8+AG8)
A9: ='midterms'!A9 | B9: ='midterms'!B9 | C9: =IF('midterms'!C9="","",'midterms'!C9) | D9: =IF('midterms'!D9="","",'midterms'!D9) | E9: =IF('midterms'!E9="","",'midterms'!E9) | F9: =IF('midterms'!F9="","",'midterms'!F9) | G9: =IF('midterms'!G9="","",'midterms'!G9) | H9: =IF('midterms'!H9="","",'midterms'!H9) | I9: =IF('midterms'!I9="","",'midterms'!I9) | J9: =IF('midterms'!J9="","",'midterms'!J9) | ... P9: =IF('midterms'!P9="","",'midterms'!P9) | Q9: =IF('finals'!C9="","",'finals'!C9) | R9: =IF('finals'!D9="","",'finals'!D9) | S9: =IF('finals'!E9="","",'finals'!E9) | T9: =IF('finals'!F9="","",'finals'!F9) | U9: =IF('finals'!G9="","",'finals'!G9) | V9: =IF('finals'!H9="","",'finals'!H9) | W9: =IF('finals'!I9="","",'finals'!I9) | X9: =IF('finals'!J9="","",'finals'!J9) | ... AD9: =IF('finals'!P9="","",'finals'!P9) | AE9: ='midterms'!Q9 | AG9: ='finals'!Q9 | AI9: =IF(OR(AE9="",AG9=""),IF(AND(AE9="",AG9=""),"",IF(AE9="",AG9,AE9)),AE9+AG9)
A10: ='midterms'!A10 | B10: ='midterms'!B10 | C10: =IF('midterms'!C10="","",'midterms'!C10) | D10: =IF('midterms'!D10="","",'midterms'!D10) | E10: =IF('midterms'!E10="","",'midterms'!E10) | F10: =IF('midterms'!F10="","",'midterms'!F10) | G10: =IF('midterms'!G10="","",'midterms'!G10) | H10: =IF('midterms'!H10="","",'midterms'!H10) | I10: =IF('midterms'!I10="","",'midterms'!I10) | J10: =IF('midterms'!J10="","",'midterms'!J10) | ... P10: =IF('midterms'!P10="","",'midterms'!P10) | Q10: =IF('finals'!C10="","",'finals'!C10) | R10: =IF('finals'!D10="","",'finals'!D10) | S10: =IF('finals'!E10="","",'finals'!E10) | T10: =IF('finals'!F10="","",'finals'!F10) | U10: =IF('finals'!G10="","",'finals'!G10) | V10: =IF('finals'!H10="","",'finals'!H10) | W10: =IF('finals'!I10="","",'finals'!I10) | X10: =IF('finals'!J10="","",'finals'!J10) | ... AD10: =IF('finals'!P10="","",'finals'!P10) | AE10: ='midterms'!Q10 | AG10: ='finals'!Q10 | AI10: =IF(OR(AE10="",AG10=""),IF(AND(AE10="",AG10=""),"",IF(AE10="",AG10,AE10)),AE10+AG10)
A11: ='midterms'!A11 | B11: ='midterms'!B11 | C11: =IF('midterms'!C11="","",'midterms'!C11) | D11: =IF('midterms'!D11="","",'midterms'!D11) | E11: =IF('midterms'!E11="","",'midterms'!E11) | F11: =IF('midterms'!F11="","",'midterms'!F11) | G11: =IF('midterms'!G11="","",'midterms'!G11) | H11: =IF('midterms'!H11="","",'midterms'!H11) | I11: =IF('midterms'!I11="","",'midterms'!I11) | J11: =IF('midterms'!J11="","",'midterms'!J11) | ... P11: =IF('midterms'!P11="","",'midterms'!P11) | Q11: =IF('finals'!C11="","",'finals'!C11) | R11: =IF('finals'!D11="","",'finals'!D11) | S11: =IF('finals'!E11="","",'finals'!E11) | T11: =IF('finals'!F11="","",'finals'!F11) | U11: =IF('finals'!G11="","",'finals'!G11) | V11: =IF('finals'!H11="","",'finals'!H11) | W11: =IF('finals'!I11="","",'finals'!I11) | X11: =IF('finals'!J11="","",'finals'!J11) | ... AD11: =IF('finals'!P11="","",'finals'!P11) | AE11: ='midterms'!Q11 | AG11: ='finals'!Q11 | AI11: =IF(OR(AE11="",AG11=""),IF(AND(AE11="",AG11=""),"",IF(AE11="",AG11,AE11)),AE11+AG11)
A12: ='midterms'!A12 | B12: ='midterms'!B12 | C12: =IF('midterms'!C12="","",'midterms'!C12) | D12: =IF('midterms'!D12="","",'midterms'!D12) | E12: =IF('midterms'!E12="","",'midterms'!E12) | F12: =IF('midterms'!F12="","",'midterms'!F12) | G12: =IF('midterms'!G12="","",'midterms'!G12) | H12: =IF('midterms'!H12="","",'midterms'!H12) | I12: =IF('midterms'!I12="","",'midterms'!I12) | J12: =IF('midterms'!J12="","",'midterms'!J12) | ... P12: =IF('midterms'!P12="","",'midterms'!P12) | Q12: =IF('finals'!C12="","",'finals'!C12) | R12: =IF('finals'!D12="","",'finals'!D12) | S12: =IF('finals'!E12="","",'finals'!E12) | T12: =IF('finals'!F12="","",'finals'!F12) | U12: =IF('finals'!G12="","",'finals'!G12) | V12: =IF('finals'!H12="","",'finals'!H12) | W12: =IF('finals'!I12="","",'finals'!I12) | X12: =IF('finals'!J12="","",'finals'!J12) | ... AD12: =IF('finals'!P12="","",'finals'!P12) | AE12: ='midterms'!Q12 | AG12: ='finals'!Q12 | AI12: =IF(OR(AE12="",AG12=""),IF(AND(AE12="",AG12=""),"",IF(AE12="",AG12,AE12)),AE12+AG12)
A13: ='midterms'!A13 | B13: ='midterms'!B13 | C13: =IF('midterms'!C13="","",'midterms'!C13) | D13: =IF('midterms'!D13="","",'midterms'!D13) | E13: =IF('midterms'!E13="","",'midterms'!E13) | F13: =IF('midterms'!F13="","",'midterms'!F13) | G13: =IF('midterms'!G13="","",'midterms'!G13) | H13: =IF('midterms'!H13="","",'midterms'!H13) | I13: =IF('midterms'!I13="","",'midterms'!I13) | J13: =IF('midterms'!J13="","",'midterms'!J13) | ... P13: =IF('midterms'!P13="","",'midterms'!P13) | Q13: =IF('finals'!C13="","",'finals'!C13) | R13: =IF('finals'!D13="","",'finals'!D13) | S13: =IF('finals'!E13="","",'finals'!E13) | T13: =IF('finals'!F13="","",'finals'!F13) | U13: =IF('finals'!G13="","",'finals'!G13) | V13: =IF('finals'!H13="","",'finals'!H13) | W13: =IF('finals'!I13="","",'finals'!I13) | X13: =IF('finals'!J13="","",'finals'!J13) | ... AD13: =IF('finals'!P13="","",'finals'!P13) | AE13: ='midterms'!Q13 | AG13: ='finals'!Q13 | AI13: =IF(OR(AE13="",AG13=""),IF(AND(AE13="",AG13=""),"",IF(AE13="",AG13,AE13)),AE13+AG13)
A14: ='midterms'!A14 | B14: ='midterms'!B14 | C14: =IF('midterms'!C14="","",'midterms'!C14) | D14: =IF('midterms'!D14="","",'midterms'!D14) | E14: =IF('midterms'!E14="","",'midterms'!E14) | F14: =IF('midterms'!F14="","",'midterms'!F14) | G14: =IF('midterms'!G14="","",'midterms'!G14) | H14: =IF('midterms'!H14="","",'midterms'!H14) | I14: =IF('midterms'!I14="","",'midterms'!I14) | J14: =IF('midterms'!J14="","",'midterms'!J14) | ... P14: =IF('midterms'!P14="","",'midterms'!P14) | Q14: =IF('finals'!C14="","",'finals'!C14) | R14: =IF('finals'!D14="","",'finals'!D14) | S14: =IF('finals'!E14="","",'finals'!E14) | T14: =IF('finals'!F14="","",'finals'!F14) | U14: =IF('finals'!G14="","",'finals'!G14) | V14: =IF('finals'!H14="","",'finals'!H14) | W14: =IF('finals'!I14="","",'finals'!I14) | X14: =IF('finals'!J14="","",'finals'!J14) | ... AD14: =IF('finals'!P14="","",'finals'!P14) | AE14: ='midterms'!Q14 | AG14: ='finals'!Q14 | AI14: =IF(OR(AE14="",AG14=""),IF(AND(AE14="",AG14=""),"",IF(AE14="",AG14,AE14)),AE14+AG14)
... A44: ='midterms'!A44 | B44: ='midterms'!B44 | C44: =IF('midterms'!C44="","",'midterms'!C44) | D44: =IF('midterms'!D44="","",'midterms'!D44) | E44: =IF('midterms'!E44="","",'midterms'!E44) | F44: =IF('midterms'!F44="","",'midterms'!F44) | G44: =IF('midterms'!G44="","",'midterms'!G44) | H44: =IF('midterms'!H44="","",'midterms'!H44) | I44: =IF('midterms'!I44="","",'midterms'!I44) | J44: =IF('midterms'!J44="","",'midterms'!J44) | ... P44: =IF('midterms'!P44="","",'midterms'!P44) | Q44: =IF('finals'!C44="","",'finals'!C44) | R44: =IF('finals'!D44="","",'finals'!D44) | S44: =IF('finals'!E44="","",'finals'!E44) | T44: =IF('finals'!F44="","",'finals'!F44) | U44: =IF('finals'!G44="","",'finals'!G44) | V44: =IF('finals'!H44="","",'finals'!H44) | W44: =IF('finals'!I44="","",'finals'!I44) | X44: =IF('finals'!J44="","",'finals'!J44) | ... AD44: =IF('finals'!P44="","",'finals'!P44) | AE44: ='midterms'!Q44 | AG44: ='finals'!Q44 | AI44: =IF(OR(AE44="",AG44=""),IF(AND(AE44="",AG44=""),"",IF(AE44="",AG44,AE44)),AE44+AG44)

Sheet summary
A1: Attendance Summary
A2: Rules: blanks ignored (not absent). Attended = codes 1-4. Absent = code 0 only. Marked = attended + absent (only days entered). Presence % = attended / marked. Quality % = average weight (1=1, 2=0.75, 3=0.69, 4=0.63, 0=0). Source: all tab (live).
A4: CLASS SNAPSHOT
A5: Students | B5: 42
A6: Class presence avg | B6: =IFERROR(AVERAGEIF(E51:E92,">0",F51:F92),"-")
A7: Class quality avg | B7: =IFERROR(AVERAGEIF(E51:E92,">0",G51:G92),"-")
A8: Most attended | B8: =IF(COUNTIF($E$51:$E$92,">0")=0,"-",IF(MAX($F$51:$F$92)=MIN($F$51:$F$92),"Tied (all equal Presence %)",IFERROR(INDEX($B$51:$B$92,MATCH(MAX($F$51:$F$92),$F$51:$F$92,0))&IF(COUNTIF($F$51:$F$92,MAX($F$51:$F$92))>1," (+ties - see Flag)",""),"-")))
A9: Most absent | B9: =IF(COUNTIF($E$51:$E$92,">0")=0,"-",IF(MAX($F$51:$F$92)=MIN($F$51:$F$92),"Tied (all equal Presence %)",IFERROR(INDEX($B$51:$B$92,MATCH(MIN($F$51:$F$92),$F$51:$F$92,0))&IF(COUNTIF($F$51:$F$92,MIN($F$51:$F$92))>1," (+ties - see Flag)",""),"-")))
A10: Note | B10: Presence % ignores blanks. Absent = marked 0 only. Flag uses Presence %. Ties: each tied student is flagged; snapshot shows one name + "(+ties)".
A18: BY DAY
A19: # | B19: Date | C19: Week | D19: Attended | E19: Absent | F19: Marked | G19: Day rate
A20: 1 | B20: ='all'!C2 | C20: ='all'!C1 | D20: =SUMPRODUCT(('all'!C$3:C$44>=1)*('all'!C$3:C$44<=4)*1) | E20: =SUMPRODUCT(--('all'!C$3:C$44=0)) | F20: =D20+E20 | G20: =IF(F20=0,"-",D20/F20)
A21: 2 | B21: ='all'!D2 | C21: ='all'!C1 | D21: =SUMPRODUCT(('all'!D$3:D$44>=1)*('all'!D$3:D$44<=4)*1) | E21: =SUMPRODUCT(--('all'!D$3:D$44=0)) | F21: =D21+E21 | G21: =IF(F21=0,"-",D21/F21)
A22: 3 | B22: ='all'!E2 | C22: ='all'!E1 | D22: =SUMPRODUCT(('all'!E$3:E$44>=1)*('all'!E$3:E$44<=4)*1) | E22: =SUMPRODUCT(--('all'!E$3:E$44=0)) | F22: =D22+E22 | G22: =IF(F22=0,"-",D22/F22)
A23: 4 | B23: ='all'!F2 | C23: ='all'!E1 | D23: =SUMPRODUCT(('all'!F$3:F$44>=1)*('all'!F$3:F$44<=4)*1) | E23: =SUMPRODUCT(--('all'!F$3:F$44=0)) | F23: =D23+E23 | G23: =IF(F23=0,"-",D23/F23)
A24: 5 | B24: ='all'!G2 | C24: ='all'!G1 | D24: =SUMPRODUCT(('all'!G$3:G$44>=1)*('all'!G$3:G$44<=4)*1) | E24: =SUMPRODUCT(--('all'!G$3:G$44=0)) | F24: =D24+E24 | G24: =IF(F24=0,"-",D24/F24)
A25: 6 | B25: ='all'!H2 | C25: ='all'!G1 | D25: =SUMPRODUCT(('all'!H$3:H$44>=1)*('all'!H$3:H$44<=4)*1) | E25: =SUMPRODUCT(--('all'!H$3:H$44=0)) | F25: =D25+E25 | G25: =IF(F25=0,"-",D25/F25)
A26: 7 | B26: ='all'!I2 | C26: ='all'!I1 | D26: =SUMPRODUCT(('all'!I$3:I$44>=1)*('all'!I$3:I$44<=4)*1) | E26: =SUMPRODUCT(--('all'!I$3:I$44=0)) | F26: =D26+E26 | G26: =IF(F26=0,"-",D26/F26)
A27: 8 | B27: ='all'!J2 | C27: ='all'!I1 | D27: =SUMPRODUCT(('all'!J$3:J$44>=1)*('all'!J$3:J$44<=4)*1) | E27: =SUMPRODUCT(--('all'!J$3:J$44=0)) | F27: =D27+E27 | G27: =IF(F27=0,"-",D27/F27)
A28: 9 | B28: ='all'!K2 | C28: ='all'!K1 | D28: =SUMPRODUCT(('all'!K$3:K$44>=1)*('all'!K$3:K$44<=4)*1) | E28: =SUMPRODUCT(--('all'!K$3:K$44=0)) | F28: =D28+E28 | G28: =IF(F28=0,"-",D28/F28)
A29: 10 | B29: ='all'!L2 | C29: ='all'!K1 | D29: =SUMPRODUCT(('all'!L$3:L$44>=1)*('all'!L$3:L$44<=4)*1) | E29: =SUMPRODUCT(--('all'!L$3:L$44=0)) | F29: =D29+E29 | G29: =IF(F29=0,"-",D29/F29)
A30: 11 | B30: ='all'!M2 | C30: ='all'!M1 | D30: =SUMPRODUCT(('all'!M$3:M$44>=1)*('all'!M$3:M$44<=4)*1) | E30: =SUMPRODUCT(--('all'!M$3:M$44=0)) | F30: =D30+E30 | G30: =IF(F30=0,"-",D30/F30)
A31: 12 | B31: ='all'!N2 | C31: ='all'!M1 | D31: =SUMPRODUCT(('all'!N$3:N$44>=1)*('all'!N$3:N$44<=4)*1) | E31: =SUMPRODUCT(--('all'!N$3:N$44=0)) | F31: =D31+E31 | G31: =IF(F31=0,"-",D31/F31)
A32: 13 | B32: ='all'!O2 | C32: ='all'!O1 | D32: =SUMPRODUCT(('all'!O$3:O$44>=1)*('all'!O$3:O$44<=4)*1) | E32: =SUMPRODUCT(--('all'!O$3:O$44=0)) | F32: =D32+E32 | G32: =IF(F32=0,"-",D32/F32)
A33: 14 | B33: ='all'!P2 | C33: ='all'!O1 | D33: =SUMPRODUCT(('all'!P$3:P$44>=1)*('all'!P$3:P$44<=4)*1) | E33: =SUMPRODUCT(--('all'!P$3:P$44=0)) | F33: =D33+E33 | G33: =IF(F33=0,"-",D33/F33)
A34: 15 | B34: ='all'!Q2 | C34: ='all'!Q1 | D34: =SUMPRODUCT(('all'!Q$3:Q$44>=1)*('all'!Q$3:Q$44<=4)*1) | E34: =SUMPRODUCT(--('all'!Q$3:Q$44=0)) | F34: =D34+E34 | G34: =IF(F34=0,"-",D34/F34)
A35: 16 | B35: ='all'!R2 | C35: ='all'!Q1 | D35: =SUMPRODUCT(('all'!R$3:R$44>=1)*('all'!R$3:R$44<=4)*1) | E35: =SUMPRODUCT(--('all'!R$3:R$44=0)) | F35: =D35+E35 | G35: =IF(F35=0,"-",D35/F35)
A36: 17 | B36: ='all'!S2 | C36: ='all'!S1 | D36: =SUMPRODUCT(('all'!S$3:S$44>=1)*('all'!S$3:S$44<=4)*1) | E36: =SUMPRODUCT(--('all'!S$3:S$44=0)) | F36: =D36+E36 | G36: =IF(F36=0,"-",D36/F36)
A37: 18 | B37: ='all'!T2 | C37: ='all'!S1 | D37: =SUMPRODUCT(('all'!T$3:T$44>=1)*('all'!T$3:T$44<=4)*1) | E37: =SUMPRODUCT(--('all'!T$3:T$44=0)) | F37: =D37+E37 | G37: =IF(F37=0,"-",D37/F37)
A38: 19 | B38: ='all'!U2 | C38: ='all'!U1 | D38: =SUMPRODUCT(('all'!U$3:U$44>=1)*('all'!U$3:U$44<=4)*1) | E38: =SUMPRODUCT(--('all'!U$3:U$44=0)) | F38: =D38+E38 | G38: =IF(F38=0,"-",D38/F38)
A39: 20 | B39: ='all'!V2 | C39: ='all'!U1 | D39: =SUMPRODUCT(('all'!V$3:V$44>=1)*('all'!V$3:V$44<=4)*1) | E39: =SUMPRODUCT(--('all'!V$3:V$44=0)) | F39: =D39+E39 | G39: =IF(F39=0,"-",D39/F39)
A40: 21 | B40: ='all'!W2 | C40: ='all'!W1 | D40: =SUMPRODUCT(('all'!W$3:W$44>=1)*('all'!W$3:W$44<=4)*1) | E40: =SUMPRODUCT(--('all'!W$3:W$44=0)) | F40: =D40+E40 | G40: =IF(F40=0,"-",D40/F40)
A41: 22 | B41: ='all'!X2 | C41: ='all'!W1 | D41: =SUMPRODUCT(('all'!X$3:X$44>=1)*('all'!X$3:X$44<=4)*1) | E41: =SUMPRODUCT(--('all'!X$3:X$44=0)) | F41: =D41+E41 | G41: =IF(F41=0,"-",D41/F41)
A42: 23 | B42: ='all'!Y2 | C42: ='all'!Y1 | D42: =SUMPRODUCT(('all'!Y$3:Y$44>=1)*('all'!Y$3:Y$44<=4)*1) | E42: =SUMPRODUCT(--('all'!Y$3:Y$44=0)) | F42: =D42+E42 | G42: =IF(F42=0,"-",D42/F42)
A43: 24 | B43: ='all'!Z2 | C43: ='all'!Y1 | D43: =SUMPRODUCT(('all'!Z$3:Z$44>=1)*('all'!Z$3:Z$44<=4)*1) | E43: =SUMPRODUCT(--('all'!Z$3:Z$44=0)) | F43: =D43+E43 | G43: =IF(F43=0,"-",D43/F43)
A44: 25 | B44: ='all'!AA2 | C44: ='all'!AA1 | D44: =SUMPRODUCT(('all'!AA$3:AA$44>=1)*('all'!AA$3:AA$44<=4)*1) | E44: =SUMPRODUCT(--('all'!AA$3:AA$44=0)) | F44: =D44+E44 | G44: =IF(F44=0,"-",D44/F44)
A45: 26 | B45: ='all'!AB2 | C45: ='all'!AA1 | D45: =SUMPRODUCT(('all'!AB$3:AB$44>=1)*('all'!AB$3:AB$44<=4)*1) | E45: =SUMPRODUCT(--('all'!AB$3:AB$44=0)) | F45: =D45+E45 | G45: =IF(F45=0,"-",D45/F45)
A46: 27 | B46: ='all'!AC2 | C46: ='all'!AC1 | D46: =SUMPRODUCT(('all'!AC$3:AC$44>=1)*('all'!AC$3:AC$44<=4)*1) | E46: =SUMPRODUCT(--('all'!AC$3:AC$44=0)) | F46: =D46+E46 | G46: =IF(F46=0,"-",D46/F46)
A47: 28 | B47: ='all'!AD2 | C47: ='all'!AC1 | D47: =SUMPRODUCT(('all'!AD$3:AD$44>=1)*('all'!AD$3:AD$44<=4)*1) | E47: =SUMPRODUCT(--('all'!AD$3:AD$44=0)) | F47: =D47+E47 | G47: =IF(F47=0,"-",D47/F47)
A49: BY STUDENT
...
